<?xml version="1.0"?>
<robot name="drone">
    <link name="drone_body">
	<visual>
		<origin rpy="0.0 0.0 0.7853" xyz="0 0 0"/>
        <!-- our dynamic follow + shape pattern instead of x. So we should rotate it firstly -->
		<geometry>
		     <mesh filename="package://mydrone/meshs/drone_body.dae"/> 
		    <!-- <mesh filename="package://urdf_tutorial/meshes/l_finger.dae"/> -->
		</geometry>
	</visual>
    </link>

    <link name="hole1">
        <origin rpy="0.0 0 0" xyz="0 0 0"/>
    </link>
    <link name="hole2">
        <origin rpy="0.0 0 0" xyz="0 0 0"/>
    </link>
    <link name="hole3">
        <origin rpy="0.0 0 0" xyz="0 0 0"/>
    </link>
    <link name="hole4">
        <origin rpy="0.0 0 0" xyz="0 0 0"/>
    </link>

    <link name="propeller1">
	<visual>
		<origin rpy="0.0 0 0" xyz="0 0 0"/>
		<geometry>
		    <mesh filename="package://mydrone/meshs/propeller.dae"/>
		</geometry>
	</visual>
    </link>
    <link name="propeller2">
	<visual>
		<origin rpy="0.0 0 0" xyz="0 0 0"/>
		<geometry>
		    <mesh filename="package://mydrone/meshs/propeller.dae"/>
		</geometry>
	</visual>
    </link>
    <link name="propeller3">
	<visual>
		<origin rpy="0.0 0 0" xyz="0 0 0"/>
		<geometry>
		    <mesh filename="package://mydrone/meshs/propeller.dae"/>
		</geometry>
	</visual>
    </link>
    <link name="propeller4">
	<visual>
		<origin rpy="0.0 0 0" xyz="0 0 0"/>
		<geometry>
		    <mesh filename="package://mydrone/meshs/propeller.dae"/>
		</geometry>
	</visual>
    </link>

    <joint name="l1" type="fixed">
        <origin xyz="0.35 0.35 0.0" />
        <parent link="drone_body"/>
        <child  link="hole1"/>
    </joint>
    <joint name="l2" type="fixed">
        <origin xyz="-0.35 0.35 0.0" />
        <parent link="drone_body"/>
        <child  link="hole2"/>
    </joint>
    <joint name="l3" type="fixed">
        <origin xyz="0.35 -0.35 0.0" />
        <parent link="drone_body"/>
        <child  link="hole3"/>
    </joint>
    <joint name="l4" type="fixed">
        <origin xyz="-0.35 -0.35 0.0" />
        <parent link="drone_body"/>
        <child  link="hole4"/>
    </joint>

    <joint name="p1" type="continuous">
	<axis xyz="0 0 1"/>
        <origin xyz="0.0 0.0 0.1" />
        <parent link="hole1"/>
        <child  link="propeller1"/>
    </joint>
    <joint name="p2" type="continuous">
        <origin xyz="0.0 0.0 0.1" />
	<axis xyz="0 0 -1"/>
        <parent link="hole2"/>
        <child  link="propeller2"/>
    </joint>
    <joint name="p3" type="continuous">
	<axis xyz="0 0 -1"/>
        <origin xyz="0.0 0.0 0.1" />
        <parent link="hole3"/>
        <child  link="propeller3"/>
    </joint>
    <joint name="p4" type="continuous">
	<axis xyz="0 0 1"/>
        <origin xyz="0.0 0.0 0.1" />
        <parent link="hole4"/>
        <child  link="propeller4"/>
    </joint>

</robot>
